<mujoco model="kobuki_standalone">
<compiler angle="radian" />
<option integrator="Euler" timestep="0.002" />
<asset>
    <texture type="2d" name="kobuki_color" file="main_body.png"/>
    <material name="kobuki" texture="kobuki_color" specular="0.5" shininess="0.25"/>
    <texture type="2d" name="wheel_color" file="wheel.png"/>
    <material name="wheel" texture="wheel_color" specular="0.5" shininess="0.25"/>
    <mesh name="main_body" file="kobuki.obj" scale="200 200 200"/>
    <mesh name="wheel" file="wheel.obj" scale="200 200 200"/>
    <material name="Black_Acrylic" rgba="0.070360 0.070360 0.070360 1"/>
    <material name="Cameras_Gray" rgba="0.296138 0.296138 0.296138 1"/>
    <material name="IR_Emitter_Lens" rgba="0.287440 0.665387 0.327778 1"/>
    <material name="IR_Lens" rgba="0.035601 0.035601 0.035601 1"/>
    <material name="IR_Rim" rgba="0.799102 0.806952 0.799103 1"/>
    <material name="Metal_Casing" rgba="1 1 1 1"/>
    <material name="RGB_Pupil" rgba="0.087140 0.002866 0.009346 1"/>

    <mesh file="d435i_0.obj" scale="200 200 200"/>
    <mesh file="d435i_1.obj" scale="200 200 200"/>
    <mesh file="d435i_2.obj" scale="200 200 200"/>
    <mesh file="d435i_3.obj" scale="200 200 200"/>
    <mesh file="d435i_4.obj" scale="200 200 200"/>
    <mesh file="d435i_5.obj" scale="200 200 200"/>
    <mesh file="d435i_6.obj" scale="200 200 200"/>
    <mesh file="d435i_7.obj" scale="200 200 200"/>
    <mesh file="d435i_8.obj" scale="200 200 200"/>
    <texture type="2d" name="d435i_color" file="d435i.png"/>
    <material name="d435i_material" texture="d435i_color" specular="0.5" shininess="0.25"/>
</asset>
    <worldbody>
        <body name="base_link" pos="700 700 10">
        <geom type="mesh" mesh="main_body" pos="0 0 0.05199" />
        <geom type="cylinder" size="0.356 0.10938" pos="0 0 0.11898" />
        <inertial pos="0.01 0 0" mass="2.4" diaginertia="0.019995 0.019995 0.03675" />
        <body name="wheel_left_link" pos="0 0.115 0.025">
        <geom type="mesh" mesh="wheel" />
        <joint name="wheel_left_joint" type="hinge" axis="0 0 1" />
        <inertial pos="0 0 0" mass="0.01" diaginertia="0.001 0.001 0.001" />
        </body>
        <body name="wheel_right_link" pos="0 -0.115 0.025">
        <geom type="mesh" mesh="wheel" />
        <joint name="wheel_right_joint" type="hinge" axis="0 0 1" />
        <inertial pos="0 0 0" mass="0.01" diaginertia="0.001 0.001 0.001" />
        </body>
            <body name="d435i" pos="0 0 9" euler="-1.57 0.8 0">
            <geom mesh="d435i_0" material="IR_Lens" class="visual_collision"/>
            <geom mesh="d435i_1" material="IR_Emitter_Lens" class="visual_collision"/>
            <geom mesh="d435i_2" material="IR_Rim" class="visual_collision"/>
            <geom mesh="d435i_3" material="IR_Lens" class="visual_collision"/>
            <geom mesh="d435i_4" material="Cameras_Gray" class="visual_collision"/>
            <geom mesh="d435i_5" material="Black_Acrylic" class="visual_collision"/>
            <geom mesh="d435i_6" material="Black_Acrylic" class="visual_collision"/>
            <geom mesh="d435i_7" material="RGB_Pupil" class="visual_collision"/>
            <geom mesh="d435i_8" mass="0.072" material="Metal_Casing" class="visual_collision"/>
            <geom class="no_visual_collision" type="capsule" mesh="d435i_8"/>
            <camera name="d435i_camera" pos="0 0 0" euler="0 0 0" />
        </body>
        </body>
    </worldbody>
<actuator>
    <motor joint="wheel_left_joint" name="wheel_left_motor" ctrlrange="-1 1" gear="50" />
    <motor joint="wheel_right_joint" name="wheel_right_motor" ctrlrange="-1 1" gear="50" />
</actuator>

</mujoco>
